Workbook

Sheet Sheet2
A1: OT
A2: OT-50811 | B2: 45870 | C2: 45870 | D2: 45873 | E2: 45871 | F2: 2266 | G2: Jose Ruben Hernandez Ruiz | H2: 7247XC | I2: USIMECA | J2: Sis Cd Hidalgo
A3: OT-50812 | B3: 45870 | C3: 45870 | D3: 45873 | E3: 45871 | F3: 2045 | G3: Ariel Ines Simbron Avila | H3: 5000XC | I3: USIMECA | J3: Sis Cd Hidalgo
A4: OT-50813 | B4: 45870 | C4: 45870 | D4: 45873 | E4: 45871 | F4: 1867 | G4: Jose Juan Olvera Marquez | H4: 2619XC | I4: USIMECA | J4: Sis Cd Hidalgo
A5: OT-50814 | B5: 45870 | C5: 45870 | D5: 45873 | E5: 45871 | F5: 2379 | G5: Enrique Cruz Hernandez | H5: 4544XC | I5: USIMECA | J5: Sis Cd Hidalgo
A6: OT-50815 | B6: 45870 | C6: 45870 | D6: 45873 | E6: 45871 | F6: 2344 | G6: Luis Alberto Perez Rendon | H6: 5510XC | I6: USIMECA | J6: Sis Cd Hidalgo
A7: OT-50816 | B7: 45870 | C7: 45870 | D7: 45873 | E7: 45871 | F7: 2260 | G7: Jesus Manuel Villalpa Islas | H7: 4659XC | I7: USIMECA | J7: Sis Cd Hidalgo
A11: 2266 | B11: Jose Ruben Hernandez Ruiz
A12: 2045 | B12: Ariel Ines Simbron Avila
A13: 1867 | B13: Jose Juan Olvera Marquez
A14: 2379 | B14: Enrique Cruz Hernandez
A15: 2344 | B15: Luis Alberto Perez Rendon
A16: 2260 | B16: Jesus Manuel Villalpa Islas

Sheet Guia de tarjetas
B2: Matricula | C2: Nombre | D2: Fecha de Nacimiento | E2: Nombres | F2: Apellidos | G2: Número de tarjeta | H2: Vencimiento | I2: CVV | J2: Reserva | K2: Número de Reserva | L2: Costo | M2: Costo por cambio | N2: Suma con cambio | O2: COMENTARIOS | P2: OT
B3: =INDEX(TUSA!$A:$A,MATCH($C3,TUSA!$BK:$BK,0),1) -> 2219 | C3: Francisco Gabriel Lopez Vertis | D3: =INDEX(TUSA!F:$F,MATCH($C3,TUSA!$BK:$BK,0),1) -> 32454 | E3: =INDEX(TUSA!D:D,MATCH($C3,TUSA!$BK:$BK,0),1) -> Francisco Gabriel | F3: {=INDEX(TUSA!B:B&" "&TUSA!C:C,MATCH($C3,TUSA!$BK:$BK,0),1)} -> Lopez Vertis | G3: =+VLOOKUP(B3,Tarjetas!$B:$K,3,FALSE()) -> 5227940202759980 | H3: =+VLOOKUP(B3,Tarjetas!$B:$K,10,FALSE()) -> 45836 | I3: =+VLOOKUP(B3,Tarjetas!$B:$K,9,FALSE()) -> 463 | J3: Martes 12:33 | K3: RY2CKY | L3: 2389 | M3: 422 | N3: =+Table4[[#This Row],[Costo]]+Table4[[#This Row],[Costo por cambio]] -> 2811 | O3: YA VOLÓ | P3: OT-5081166
B4: =INDEX(TUSA!$A:$A,MATCH($C4,TUSA!$BK:$BK,0),1) -> 2358 | C4: Angel Abraham Lopez Romero | D4: =INDEX(TUSA!F:$F,MATCH($C4,TUSA!$BK:$BK,0),1) -> 37288 | E4: =INDEX(TUSA!D:D,MATCH($C4,TUSA!$BK:$BK,0),1) -> Angel Abraham | F4: {=INDEX(TUSA!B:B&" "&TUSA!C:C,MATCH($C4,TUSA!$BK:$BK,0),1)} -> Lopez Romero | G4: =+VLOOKUP(B4,Tarjetas!$B:$K,3,FALSE()) -> 5227940202997270 | H4: =+VLOOKUP(B4,Tarjetas!$B:$K,10,FALSE()) -> 46019 | I4: =+VLOOKUP(B4,Tarjetas!$B:$K,9,FALSE()) -> 634 | J4: Martes 12:33 | K4: LYVRFF | L4: 2386 | M4: 464 | N4: =+Table4[[#This Row],[Costo]]+Table4[[#This Row],[Costo por cambio]] -> 2850 | O4: YA VOLÓ | P4: OT-5081164
B5: =INDEX(TUSA!$A:$A,MATCH($C5,TUSA!$BK:$BK,0),1) -> 2378 | C5: Guillermo Hernandez Abundiz | D5: =INDEX(TUSA!F:$F,MATCH($C5,TUSA!$BK:$BK,0),1) -> 32714 | E5: =INDEX(TUSA!D:D,MATCH($C5,TUSA!$BK:$BK,0),1) -> Guillermo | F5: {=INDEX(TUSA!B:B&" "&TUSA!C:C,MATCH($C5,TUSA!$BK:$BK,0),1)} -> Hernandez Abundiz | G5: =+VLOOKUP(B5,Tarjetas!$B:$K,3,FALSE()) -> 5227940203167610 | H5: =+VLOOKUP(B5,Tarjetas!$B:$K,10,FALSE()) -> 47150 | I5: =+VLOOKUP(B5,Tarjetas!$B:$K,9,FALSE()) -> 474 | J5: Martes 12:33 | K5: BGL7NQ | L5: 2399 | M5: 422 | N5: =+Table4[[#This Row],[Costo]]+Table4[[#This Row],[Costo por cambio]] -> 2821 | O5: YA VOLÓ | P5: OT-5081167
B6: =INDEX(TUSA!$A:$A,MATCH($C6,TUSA!$BK:$BK,0),1) -> 2386 | C6: Gabriel Fuentes Sibaja | D6: =INDEX(TUSA!F:$F,MATCH($C6,TUSA!$BK:$BK,0),1) -> 25629 | E6: =INDEX(TUSA!D:D,MATCH($C6,TUSA!$BK:$BK,0),1) -> Gabriel | F6: {=INDEX(TUSA!B:B&" "&TUSA!C:C,MATCH($C6,TUSA!$BK:$BK,0),1)} -> Fuentes Sibaja | G6: =+VLOOKUP(B6,Tarjetas!$B:$K,3,FALSE()) -> 5227940203167560 | H6: =+VLOOKUP(B6,Tarjetas!$B:$K,10,FALSE()) -> 47150 | I6: =+VLOOKUP(B6,Tarjetas!$B:$K,9,FALSE()) -> 534 | J6: Martes 12:33 | K6: A933TY | L6: 2551 | M6: 270 | N6: =+Table4[[#This Row],[Costo]]+Table4[[#This Row],[Costo por cambio]] -> 2821 | O6: YA VOLÓ | P6: OT-5081165
B8: =INDEX(TUSA!$A:$A,MATCH($C8,TUSA!$BK:$BK,0),1) -> 1818 | C8: Leonardo Moreno Lopez | D8: =INDEX(TUSA!F:$F,MATCH($C8,TUSA!$BK:$BK,0),1) -> 28621 | E8: =INDEX(TUSA!D:D,MATCH($C8,TUSA!$BK:$BK,0),1) -> Leonardo | F8: {=INDEX(TUSA!B:B&" "&TUSA!C:C,MATCH($C8,TUSA!$BK:$BK,0),1)} -> Moreno Lopez | G8: =+VLOOKUP(B8,Tarjetas!$B:$K,3,FALSE()) -> 5227940203167630 | H8: =+VLOOKUP(B8,Tarjetas!$B:$K,10,FALSE()) -> 47150 | I8: =+VLOOKUP(B8,Tarjetas!$B:$K,9,FALSE()) -> 608 | J8: Miercoles 12:33 | K8: P9D7JL | L8: 2252 | M8: 807 | N8: =+Table4[[#This Row],[Costo]]+Table4[[#This Row],[Costo por cambio]] -> 3059 | O8: CAMBIO HECHO facturado | P8: =+VLOOKUP(Table4[[#This Row],[Matricula]],OTS!A:C,3,FALSE) -> OT-5081170
B9: =INDEX(TUSA!$A:$A,MATCH($C9,TUSA!$BK:$BK,0),1) -> 2162 | C9: Jorge Brindis Juarez | D9: =INDEX(TUSA!F:$F,MATCH($C9,TUSA!$BK:$BK,0),1) -> 27208 | E9: =INDEX(TUSA!D:D,MATCH($C9,TUSA!$BK:$BK,0),1) -> Jorge | F9: {=INDEX(TUSA!B:B&" "&TUSA!C:C,MATCH($C9,TUSA!$BK:$BK,0),1)} -> Brindis Juarez | G9: =+VLOOKUP(B9,Tarjetas!$B:$K,3,FALSE()) -> 5227940202760600 | H9: =+VLOOKUP(B9,Tarjetas!$B:$K,10,FALSE()) -> 45836 | I9: =+VLOOKUP(B9,Tarjetas!$B:$K,9,FALSE()) -> 923 | J9: Miercoles 12:33 | K9: P9D7JL | L9: 2252 | M9: 807 | N9: =+Table4[[#This Row],[Costo]]+Table4[[#This Row],[Costo por cambio]] -> 3059 | O9: CAMBIO HECHO facturado | P9: =+VLOOKUP(Table4[[#This Row],[Matricula]],OTS!A:C,3,FALSE) -> OT-5081178
B11: =INDEX(TUSA!$A:$A,MATCH($C11,TUSA!$BK:$BK,0),1) -> 2370 | C11: Oscar Carmona Rocha | D11: =INDEX(TUSA!F:$F,MATCH($C11,TUSA!$BK:$BK,0),1) -> 35807 | E11: =INDEX(TUSA!D:D,MATCH($C11,TUSA!$BK:$BK,0),1) -> Oscar | F11: {=INDEX(TUSA!B:B&" "&TUSA!C:C,MATCH($C11,TUSA!$BK:$BK,0),1)} -> Carmona Rocha | G11: 5227940202997287 | H11: 12/28 | I11: =+VLOOKUP(B11,Tarjetas!$B:$K,9,FALSE()) -> 933 | J11: Miercoles 12:33 | K11: FDJC2J | L11: 2609 | M11: 426 | N11: =+Table4[[#This Row],[Costo]]+Table4[[#This Row],[Costo por cambio]] -> 3035 | O11: CAMBIO HECHO | P11: =+VLOOKUP(Table4[[#This Row],[Matricula]],OTS!A:C,3,FALSE) -> OT-5081174
B12: =INDEX(TUSA!$A:$A,MATCH($C12,TUSA!$BK:$BK,0),1) -> 2275 | C12: Salvador Vazquez Tlapalamatl | D12: =INDEX(TUSA!F:$F,MATCH($C12,TUSA!$BK:$BK,0),1) -> 38257 | E12: =INDEX(TUSA!D:D,MATCH($C12,TUSA!$BK:$BK,0),1) -> Salvador | F12: {=INDEX(TUSA!B:B&" "&TUSA!C:C,MATCH($C12,TUSA!$BK:$BK,0),1)} -> Vazquez Tlapalamatl | G12: 5227940202714179 | H12: 05/28 | I12: =+VLOOKUP(B12,Tarjetas!$B:$K,9,FALSE()) -> 75 | J12: Miercoles 12:33 | K12: VKGYPX | L12: 2609 | M12: 402 | N12: =+Table4[[#This Row],[Costo]]+Table4[[#This Row],[Costo por cambio]] -> 3011 | O12: CAMBIO HECHO | P12: =+VLOOKUP(Table4[[#This Row],[Matricula]],OTS!A:C,3,FALSE) -> OT-5081176
B13: =INDEX(TUSA!$A:$A,MATCH($C13,TUSA!$BK:$BK,0),1) -> 2218 | C13: Luis Uribe Quintero | D13: =INDEX(TUSA!F:$F,MATCH($C13,TUSA!$BK:$BK,0),1) -> 32777 | E13: =INDEX(TUSA!D:D,MATCH($C13,TUSA!$BK:$BK,0),1) -> Luis | F13: {=INDEX(TUSA!B:B&" "&TUSA!C:C,MATCH($C13,TUSA!$BK:$BK,0),1)} -> Uribe Quintero | G13: 5227940202193630 | H13: 04/27 | I13: =+VLOOKUP(B13,Tarjetas!$B:$K,9,FALSE()) -> 769 | J13: Miercoles 12:33 | K13: MK5HGH | L13: 2609 | M13: 392 | N13: =+Table4[[#This Row],[Costo]]+Table4[[#This Row],[Costo por cambio]] -> 3001 | O13: CAMBIO HECHO | P13: =+VLOOKUP(Table4[[#This Row],[Matricula]],OTS!A:C,3,FALSE) -> OT-5081177
B14: =INDEX(TUSA!$A:$A,MATCH($C14,TUSA!$BK:$BK,0),1) -> 2211 | C14: Jonathan Uribe Quintero | D14: =INDEX(TUSA!F:$F,MATCH($C14,TUSA!$BK:$BK,0),1) -> 35956 | E14: =INDEX(TUSA!D:D,MATCH($C14,TUSA!$BK:$BK,0),1) -> Jonathan | F14: {=INDEX(TUSA!B:B&" "&TUSA!C:C,MATCH($C14,TUSA!$BK:$BK,0),1)} -> Uribe Quintero | G14: 5227940202193036 | H14: 04/27 | I14: =+VLOOKUP(B14,Tarjetas!$B:$K,9,FALSE()) -> 454 | J14: Miercoles 12:33 | K14: ZJ6KWA | L14: 2609 | M14: 627 | N14: =+Table4[[#This Row],[Costo]]+Table4[[#This Row],[Costo por cambio]] -> 3236 | O14: CAMBIO HECHO | P14: =+VLOOKUP(Table4[[#This Row],[Matricula]],OTS!A:C,3,FALSE) -> OT-5081172
B15: =INDEX(TUSA!$A:$A,MATCH($C15,TUSA!$BK:$BK,0),1) -> 2195 | C15: Aurelio Jaime Perez Martinez | D15: =INDEX(TUSA!F:$F,MATCH($C15,TUSA!$BK:$BK,0),1) -> 27663 | E15: =INDEX(TUSA!D:D,MATCH($C15,TUSA!$BK:$BK,0),1) -> Aurelio Jaime | F15: {=INDEX(TUSA!B:B&" "&TUSA!C:C,MATCH($C15,TUSA!$BK:$BK,0),1)} -> Perez Martinez | G15: 5227940202714237 | H15: 05/28 | I15: =+VLOOKUP(B15,Tarjetas!$B:$K,9,FALSE()) -> 124 | J15: Miercoles 12:33 | K15: F8MCJL | L15: 2609 | M15: 617 | N15: =+Table4[[#This Row],[Costo]]+Table4[[#This Row],[Costo por cambio]] -> 3226 | O15: CAMBIO HECHO | P15: =+VLOOKUP(Table4[[#This Row],[Matricula]],OTS!A:C,3,FALSE) -> OT-5081171
B16: =INDEX(TUSA!$A:$A,MATCH($C16,TUSA!$BK:$BK,0),1) -> 2133 | C16: Martin Cuellar Campos | D16: =INDEX(TUSA!F:$F,MATCH($C16,TUSA!$BK:$BK,0),1) -> 27212 | E16: =INDEX(TUSA!D:D,MATCH($C16,TUSA!$BK:$BK,0),1) -> Martin | F16: {=INDEX(TUSA!B:B&" "&TUSA!C:C,MATCH($C16,TUSA!$BK:$BK,0),1)} -> Cuellar Campos | G16: 5227940202759943 | H16: 06/28 | I16: =+VLOOKUP(B16,Tarjetas!$B:$K,9,FALSE()) -> 538 | J16: Miercoles 12:33 | K16: XL33NH | L16: 2570 | M16: 656 | N16: =+Table4[[#This Row],[Costo]]+Table4[[#This Row],[Costo por cambio]] -> 3226 | O16: CAMBIO HECHO | P16: =+VLOOKUP(Table4[[#This Row],[Matricula]],OTS!A:C,3,FALSE) -> OT-5081169
B17: =INDEX(TUSA!$A:$A,MATCH($C17,TUSA!$BK:$BK,0),1) -> 912 | C17: Ramon Mario Hernandez Lagos | D17: =INDEX(TUSA!F:$F,MATCH($C17,TUSA!$BK:$BK,0),1) -> 23985 | E17: =INDEX(TUSA!D:D,MATCH($C17,TUSA!$BK:$BK,0),1) -> Ramon Mario | F17: {=INDEX(TUSA!B:B&" "&TUSA!C:C,MATCH($C17,TUSA!$BK:$BK,0),1)} -> Hernandez Lagos | G17: 5227940202760636 | H17: 06/28 | I17: =+VLOOKUP(B17,Tarjetas!$B:$K,9,FALSE()) -> 919 | J17: Miercoles 12:33 | K17: RYKNNI | L17: 2850 | M17: 376 | N17: =+Table4[[#This Row],[Costo]]+Table4[[#This Row],[Costo por cambio]] -> 3226 | O17: CAMBIO HECHO | P17: =+VLOOKUP(Table4[[#This Row],[Matricula]],OTS!A:C,3,FALSE) -> OT-5081179
B18: =INDEX(TUSA!$A:$A,MATCH($C18,TUSA!$BK:$BK,0),1) -> 2262 | C18: Javier Islas Valdez | D18: =INDEX(TUSA!F:$F,MATCH($C18,TUSA!$BK:$BK,0),1) -> 30892 | E18: =INDEX(TUSA!D:D,MATCH($C18,TUSA!$BK:$BK,0),1) -> Javier | F18: {=INDEX(TUSA!B:B&" "&TUSA!C:C,MATCH($C18,TUSA!$BK:$BK,0),1)} -> Islas Valdez | G18: D7156G0KGZES | H18: =+VLOOKUP(B18,Tarjetas!$B:$K,10,FALSE()) -> 45836 | I18: =+VLOOKUP(B18,Tarjetas!$B:$K,9,FALSE()) -> 578 | J18: Miercoles 12:33 | K18: OBMZ4C | L18: 2609 | M18: 440 | N18: =+Table4[[#This Row],[Costo]]+Table4[[#This Row],[Costo por cambio]] -> 3049 | O18: CAMBIO HECHO facturado | P18: =+VLOOKUP(Table4[[#This Row],[Matricula]],OTS!A:C,3,FALSE) -> OT-5081173
B19: =INDEX(TUSA!$A:$A,MATCH($C19,TUSA!$BK:$BK,0),1) -> 1990 | C19: Luis Lazcano Cuatepotzo | D19: =INDEX(TUSA!F:$F,MATCH($C19,TUSA!$BK:$BK,0),1) -> 30906 | E19: =INDEX(TUSA!D:D,MATCH($C19,TUSA!$BK:$BK,0),1) -> Luis | F19: {=INDEX(TUSA!B:B&" "&TUSA!C:C,MATCH($C19,TUSA!$BK:$BK,0),1)} -> Lazcano Cuatepotzo | G19: D7156G0KGZF9 | H19: =+VLOOKUP(B19,Tarjetas!$B:$K,10,FALSE()) -> 45836 | I19: =+VLOOKUP(B19,Tarjetas!$B:$K,9,FALSE()) -> 817 | J19: Miercoles 12:33 | K19: OBMZ4C | L19: 2609 | M19: 440 | N19: =+Table4[[#This Row],[Costo]]+Table4[[#This Row],[Costo por cambio]] -> 3049 | O19: CAMBIO HECHO facturado | P19: =+VLOOKUP(Table4[[#This Row],[Matricula]],OTS!A:C,3,FALSE) -> OT-5081175
C28: Lopez Vertis | D28: RY2CKY
C29: Lopez Romero | D29: LYVRFF
C30: Hernandez Abundiz | D30: BGL7NQ
C31: Fuentes Sibaja | D31: A933TY
C33: Moreno Lopez | D33: P9D7JL
C34: Brindis Juarez | D34: P9D7JL
C36: Carmona Rocha | D36: FDJC2J
C37: Vazquez Tlapalamatl | D37: VKGYPX
C38: Uribe Quintero | D38: MK5HGH
C39: Uribe Quintero | D39: ZJ6KWA
C40: Perez Martinez | D40: F8MCJL
C41: Cuellar Campos | D41: XL33NH
... C44: Lazcano Cuatepotzo | D44: OBMZ4C

Sheet Tarjetas
A1: id_control_tags_Up | B1: id_matricula | C1: Operador | D1: Dispositivo | E1: Fecha_alta | F1: Observaciones | G1: Usuario | H1: NIP | I1: IUT | J1: Num_Confidencial | K1: Num_Vigencia
A2: 1109 | B2: 216 | C2: Javier Carpio Segundo | D2: 5227940202047110 | E2: 45145 | F2: No-cargado | G2: Karina | H2: 6125 | I2: D0154G0IKBFA | J2: 313 | K2: 45684
A3: 1669 | B3: 283 | C3: Victorino Dominguez Olvera | D3: 5227940203167600 | E3: 45888 | F3: No-cargado | G3: AnahiL | H3: 1323 | I3: D1156G0LFGC8 | J3: 218 | K3: 47150
A4: 813 | B4: 352 | C4: Andres Hernandez Sanchez | D4: 5227940200393580 | E4: 44418 | F4: No-cargado | G4: Ariadna | H4: 3954 | I4: D3159G0FX4VH | J4: 653 | K4: 45773
A5: 1587 | B5: 623 | C5: Oswaldo Padilla Oropeza | D5: 5227940202997990 | E5: 45853 | F5: No-cargado | G5: AnahiL | H5: 4840 | I5: D9159G0L61OR | J5: 666 | K5: 46019
A6: 1492 | B6: 912 | C6: Ramon Mario Hernandez Lagos | D6: 5227940202760630 | E6: 45692 | F6: No-cargado | G6: AntonioL | H6: 5121 | I6: D7156G0KGZFE | J6: 919 | K6: 45836
A7: 1672 | B7: 1818 | C7: Leonardo Moreno Lopez | D7: 5227940203167630 | E7: 45891 | F7: No-cargado | G7: AnahiL | H7: 2761 | I7: D1156G0LFGCB | J7: 608 | K7: 47150
A8: 1562 | B8: 1867 | C8: Jose Juan Olvera Marquez | D8: 5227940202759970 | E8: 45700 | F8: No-cargado | G8: AntonioL | H8: 2464 | I8: D7155G0KGZDK | J8: 514 | K8: 45836
A9: 818 | B9: 1902 | C9: Luis Jesus Cortez Lopez | D9: 5227940200393530 | E9: 44419 | G9: Antonio | H9: 83087 | I9: D3159G0FX4VC | J9: 478 | K9: 45773
A10: 1569 | B10: 1982 | C10: Humberto Daniel Salazar Arguello | D10: 5227940202997810 | E10: 45776 | F10: No-cargado | G10: Ariadna | H10: 490 | I10: D9159G0L61O9 | J10: 673 | K10: 46019
A11: 1446 | B11: 1990 | C11: Luis Lazcano Cuatepotzo | D11: D7156G0KGZF9 | E11: 45577 | F11: No-cargado | G11: AnaJM | H11: 5544 | I11: D7156G0KGZF9 | J11: 817 | K11: 45836
A12: 961 | B12: 2039 | C12: Adrian Rodrigo Salazar Gutierrez | D12: 5227940200603850 | E12: 44795 | F12: No-cargado | G12: Antonio | H12: 6544 | I12: D6150G0G7R2P | J12: 856 | K12: 45834
A13: 1002 | B13: 2045 | C13: Ariel Ines Simbron Avila | D13: 5227940201705110 | E13: 44956 | F13: No-cargado | G13: Ariadna | H13: 917 | I13: D7150G0HORTZ | J13: 587 | K13: 45803
A14: 1571 | B14: 2050 | C14: Jose Armando Ochoa Gonzalez | D14: 5227940202997830 | E14: 45792 | F14: No-cargado | G14: AntonioL | H14: 3659 | I14: D9159G0L61OB | J14: 998 | K14: 46019
A15: 1203 | B15: 2077 | C15: Alberto Trujillo Luna | D15: 5227940202193200 | E15: 45336 | G15: Antonio | H15: 472 | I15: D1159G0IW879 | J15: 364 | K15: 45774
A16: 1014 | B16: 2083 | C16: Jose Guadalupe Escamilla Carbajal | D16: 5227940201705230 | E16: 44838 | F16: No-cargado | G16: Ariadna | H16: 9255 | I16: D7150G0HORUB | J16: 130 | K16: 45803
A17: 1381 | B17: 2105 | C17: Gabriel Flores Garrido | D17: 5227940202714100 | E17: 45664 | F17: No-cargado | G17: AnaJM | H17: 69 | I17: D7151G0KAKZO | J17: 261 | K17: 45805
A18: 1570 | B18: 2125 | C18: German Santos Lozano Lopez | D18: 5227940202997820 | E18: 45786 | F18: No-cargado | G18: AntonioL | H18: 2200 | I18: D9159G0L61OA | J18: 659 | K18: 46019
A19: 1553 | B19: 2133 | C19: Martin Cuellar Campos | D19: 5227940202759940 | E19: 45719 | F19: No-cargado | G19: AntonioL | H19: 6233 | I19: D7155G0KGZDH | J19: 538 | K19: 45836
A20: 1148 | B20: 2139 | C20: Waldo Amhed Dominguez Lopez | D20: 5227940202047570 | E20: 45044 | F20: No-cargado | G20: Vanessa | H20: 8610 | I20: D0154G0IKBGK | J20: 964 | K20: 45684
A21: 1462 | B21: 2151 | C21: Hugo Ramirez Linares | D21: D7156G0KGZEG | E21: 45699 | F21: No-cargado | G21: TaniaTC | H21: 5506 | I21: D7156G0KGZEG | J21: 400 | K21: 45836
A22: 1547 | B22: 2162 | C22: Jorge Brindis Juarez | D22: 5227940202760600 | E22: 45734 | F22: No-cargado | G22: Ariadna | H22: 7474 | I22: D7156G0KGZFB | J22: 923 | K22: 45836
A23: 1123 | B23: 2170 | C23: Luis Daniel Monroy Garduño | D23: 5227940202047250 | E23: 45100 | F23: No-cargado | G23: Karina | H23: 5137 | I23: D0154G0IKBFO | J23: 643 | K23: 45684
A24: 1103 | B24: 2172 | C24: Luis Alfonso Hernandez Huerta | D24: 5227940202047050 | E24: 45107 | F24: No-cargado | G24: Karina | H24: 5326 | I24: D0154G0IKBF4 | J24: 952 | K24: 45684
A25: 1116 | B25: 2176 | C25: Edwin Ruben Silva Rodriguez | D25: 5227940202047180 | E25: 45421 | F25: No-cargado | G25: Patricia | H25: 8503 | I25: D0154G0IKBFH | J25: 90 | K25: 45684
A26: 1146 | B26: 2184 | C26: Edgar Jesus Franco Gonzalez | D26: 5227940202047030 | E26: 45155 | F26: No-cargado | G26: Antonio | H26: 2443 | I26: D0154G0IKBF2 | J26: 619 | K26: 45684
A27: 1394 | B27: 2195 | C27: Aurelio Jaime Perez Martinez | D27: 5227940202714230 | E27: 45456 | F27: No-cargado | G27: Patricia | H27: 1839 | I27: D7151G0KAL01 | J27: 124 | K27: 45805
... A29: 1210 | B29: 2206 | C29: Rafael Vargas Garcia | D29: 5227940202193110 | E29: 45202 | F29: No-cargado | G29: AnahiM | H29: 5523 | I29: D1159G0IW870 | J29: 221 | K29: 45774
A30: 1145 | B30: 2209 | C30: Jose Rafael Ontiveros Osnaya | D30: 5227940202047020 | E30: 45217 | G30: Antonio | H30: 2353 | I30: D0154G0IKBF1 | J30: 187 | K30: 45684
A31: 1214 | B31: 2210 | C31: Julio Cesar Islas Alcantara | D31: 5227940202193070 | E31: 45222 | F31: No-cargado | G31: Patricia | H31: 0 | I31: D1159G0IW86W
A32: 1218 | B32: 2211 | C32: Jonathan Uribe Quintero | D32: 5227940202193030 | E32: 45251 | G32: Patricia | H32: 6070 | I32: D1159G0IW86S | J32: 454 | K32: 45774
A33: 1664 | B33: 2214 | C33: Adolfo Julio Cesar Romero Garcia | D33: 5227940203167550 | E33: 45874 | F33: No-cargado | G33: AnahiL | H33: 6204 | I33: D1156G0LFGC3 | J33: 107 | K33: 47150
A34: 1273 | B34: 2218 | C34: Luis Uribe Quintero | D34: 5227940202193630 | E34: 45286 | F34: No-cargado | G34: Patricia | H34: 1076 | I34: D1159G0IW88G | J34: 769 | K34: 45774
A35: 1561 | B35: 2219 | C35: Francisco Gabriel Lopez Vertis | D35: 5227940202759980 | E35: 45703 | F35: No-cargado | G35: AntonioL | H35: 941 | I35: D7155G0KGZDL | J35: 463 | K35: 45836
A36: 1470 | B36: 2225 | C36: Efren Gustavo Pineda Avila | D36: 5227940202760200 | E36: 45636 | F36: No-cargado | G36: AnaJM | H36: 3820 | I36: D7156G0KGZE7 | J36: 741 | K36: 45836
A37: 1282 | B37: 2228 | C37: Efrain Juncal Sosa | D37: 5227940202193540 | E37: 45359 | F37: No-cargado | G37: Patricia | H37: 7513 | I37: D1159G0IW887 | J37: 565 | K37: 45774
A38: 1284 | B38: 2230 | C38: Javier Peralta Ortiz | D38: 5227940202193520 | E38: 45328 | F38: No-cargado | G38: Patricia | H38: 69 | I38: D1159G0IW885 | J38: 643 | K38: 45774
A39: 1294 | B39: 2240 | C39: Marcos Hernandez Flores | D39: 5227940202193890 | E39: 45359 | F39: No-cargado | G39: Patricia | H39: 5243 | I39: D1159G0IW896 | J39: 61 | K39: 45774
A40: 1297 | B40: 2244 | C40: Oscar Romo Jimenez | D40: 5227940202193860 | E40: 45370 | F40: No-cargado | G40: Patricia | H40: 5532 | I40: D1159G0IW893 | J40: 432 | K40: 45774
A41: 1356 | B41: 2254 | C41: David Juarez Juarez | D41: 5227940202193910 | E41: 45415 | F41: No-cargado | G41: Patricia | H41: 1619 | I41: D1159G0IW898 | J41: 945 | K41: 45774
...

Sheet sheet1
A1: ID_matricula | B1: Ap_paterno | C1: Ap_materno | D1: Nombres | E1: Fecha_nacimto | F1: Lugar_nacimto | G1: Reg_fed_causantes | H1: Direccion | I1: Colonia | J1: Ciudad | K1: Estado | L1: Codigo_postal | M1: Pais | N1: Titulo | O1: Estado_estudios | P1: Cedula_profesional | Q1: Puesto | R1: Actividad | S1: Area | T1: Telefono | U1: ID_no_poliza | V1: No_cartilla | W1: Fecha_ingreso_poliza | X1: No_IMSS | Y1: Nacionalidad | Z1: No_CURP | AA1: ID_empleado | AB1: Contrato_eventual | AC1: Fecha_ingreso | AD1: Fecha_alta_IMSS | AE1: Fecha_planta | AF1: Fecha_de_baja | AG1: Sexo | AH1: Estado_civil | AI1: Pension_alimenticia | AJ1: No_oficio | AK1: Disp_para_viajar | AL1: Disp_cambio_residencia | AM1: Observaciones | AN1: Habilidades_especificas | AO1: Areas_de_experiencia | AP1: Areas_de_interes | AQ1: Correo_electronico | AR1: Fecha_baja_IMSS | AS1: No_credito_infonavit | AT1: No_credito_fonacot | AU1: No_cta_bancaria | AV1: Institucion_bancaria | AW1: Camisa | AX1: Pantalon | AY1: Zapatos | AZ1: Chamarra | BA1: ID_empresa | BB1: Sueldo_promedio | BC1: No_bimestre | BD1: Contacto | BE1: No_celular | BF1: Fecha_captura | BG1: Movto | BH1: Tarjeta_combustible | BI1: No_celular2 | BJ1: No_cred_elector | BK1: Folio_cred_elector | BL1: Observaciones2 | BM1: TiempoRastreo | BN1: tel | BO1: Id_Escolaridad | BP1: Tipo_Nomina | BQ1: Playera | BR1: Rueda_5 | BS1: Telefono2 | BT1: Mpio_nac | BU1: FechaCursoOrganizacion | BV1: FechaCemex | BW1: Login_app | BX1: Referido_por | BY1: OpLocal | BZ1: Tipo_sangre | CA1: No_Domicilio | CB1: Entre_calle1 | CC1: Entre_calle2 | CD1: Nombre
A2: 1760 | B2: Sanchez | C2: Garcia | D2: Ricardo | E2: 33743 | F2: Hidalgo | G2: SAGR920519F27 | H2: Jose Maria Pino Suarez 11 | I2: Jose Maria Pino Suarez | J2: Tepeapulco | K2: Hidalgo | L2: 43992 | M2: México | O2: TRUE | Q2: O | S2: Operativo | T2: 6677979058 | U2: 004-0000384386-00 | W2: 43890 | X2: 1312923737-9 | Y2: Mexicana | Z2: SAGR920519HHGNRC00 | AA2: 1 | AB2: TRUE | AC2: 43878 | AD2: 43878 | AF2: 44583 | AG2: M | AH2: U | AI2: FALSE | AK2: TRUE | AL2: TRUE | AN2: Manejo | AO2: Manejo de unidades torton, rabon y tractocamion | AP2: Manejo | AQ2: r.1760tusa@gmail.com | AR2: 44583 | AU2: 5256783255765290 | AV2: Banamex | AW2: 0 | AX2: 0 | AY2: 0.0 | BA2: 0 | BB2: 393.89 | BC2: 1 | BD2: FALSE | BE2: 7712405453 | BF2: 44585 | BG2: M | BJ2: 1942925497 | BK2: 1193087866327 | BM2: 10 | BO2: 2 | BP2: N | BR2: FALSE | BS2: 7752057898 | BT2: Tepeapulco | BW2: FALSE | BY2: FALSE | CD2: =+Table1[[#This Row],[Nombres]]&" "&Table1[[#This Row],[Ap_paterno]]&" "&Table1[[#This Row],[Ap_materno]] -> Ricardo Sanchez Garcia
A3: 1762 | B3: Lazcano | C3: Valencia | D3: Jessica | E3: 32997 | F3: Hidalgo | G3: LAVJ900504UZ5 | H3: Cda. Emiliano Zapata Nte SN | I3: Centro | J3: Tlanalapa | K3: Hidalgo | L3: 43930 | M3: México | N3: Licenciatura en contaduría | O3: TRUE | Q3: A | S3: Administrativo | T3: 7751537242 | U3: 53603-01 12322474 | W3: 44829 | X3: 0220905655-1 | Y3: Mexicana | Z3: LAVJ900504MHGZLS06 | AA3: 2 | AB3: TRUE | AC3: 43899 | AD3: 43899 | AE3: 45292 | AG3: F | AH3: S | AI3: FALSE | AK3: TRUE | AL3: FALSE | AN3: Contabilidad | AO3: Contabilidad general | AP3: Impuestos | AQ3: j.1762tusa@gmail.com | AU3: 5256783282383893 | AV3: Banamex | AW3: 34 | AX3: 0 | AY3: 0 | AZ3: 34 | BA3: 0 | BB3: 613.31 | BC3: 0 | BD3: FALSE | BE3: 7711896851 | BF3: 44110 | BG3: M | BJ3: 1898342092 | BK3: 1395082418806 | BM3: 10 | BN3: 7751531778 | BO3: 5 | BP3: N | BQ3: M | BR3: FALSE | BS3: 7751490555 | BT3: Tepeapulco | BW3: FALSE | BY3: FALSE | CD3: =+Table1[[#This Row],[Nombres]]&" "&Table1[[#This Row],[Ap_paterno]]&" "&Table1[[#This Row],[Ap_materno]] -> Jessica Lazcano Valencia
A4: 1764 | B4: Castro | C4: Islas | D4: Juan Carlos | E4: 31690 | F4: Hidalgo | G4: CAIJ8610059E3 | H4: Atitalaquia No. 749 | I4: Rojo Gomez | J4: Sahagun | K4: Hidalgo | L4: 43996 | M4: Mexico | N4: Ingeniería en Sistemas Computacionales | O4: TRUE | Q4: A | S4: Administrativo | U4: 0000505-0000001 | X4: 13128603050 | Y4: Mexicana | Z4: CAIJ861005HHGSSN03 | AA4: 2 | AB4: TRUE | AC4: 43913 | AD4: 43913 | AF4: 43974 | AG4: M | AH4: U | AI4: FALSE | AK4: FALSE | AL4: FALSE | AN4: Desarrollo de software | AO4: Desarrollo en Sistemas | AQ4: juan.castro@trasladosuniversales.com.mx | AR4: 43974 | AU4: 5256783056131098 | AV4: Banamex | AW4: 0 | AX4: 0 | AY4: 0.0 | BA4: 0 | BB4: 424.78 | BC4: 0 | BD4: FALSE | BF4: 44047 | BG4: M | BJ4: 1219099464368 | BK4: 1147525511 | BM4: 10 | BO4: 5 | BP4: N | BR4: FALSE | BT4: Tepeapulco | BW4: FALSE | BY4: FALSE | CD4: =+Table1[[#This Row],[Nombres]]&" "&Table1[[#This Row],[Ap_paterno]]&" "&Table1[[#This Row],[Ap_materno]] -> Juan Carlos Castro Islas
A5: 1905 | B5: Lozada | C5: Martinez | D5: Marco Antonio | E5: 32347 | F5: Puebla | G5: LOMM8807238G7 | H5: Calle Miguel Hidalgo | I5: El Paredon | J5: El Paredon | K5: Puebla | L5: 73302 | M5: Mexico | O5: TRUE | Q5: O | S5: Operativo | T5: 7751558502 | X5: 0220883833-0 | Y5: Mexicana | Z5: LOMM880723HPLZRR05 | AA5: 1 | AB5: TRUE | AC5: 44392 | AD5: 44392 | AF5: 44487 | AG5: M | AH5: U | AI5: FALSE | AK5: TRUE | AL5: FALSE | AQ5: m.1905tusa@gmail.com | AR5: 44487 | AU5: 5256783585532196 | AV5: Banamex | AW5: 36 | AX5: 32 | AY5: 26.0 | AZ5: G | BA5: 0 | BB5: 206.49 | BC5: 0 | BD5: FALSE | BF5: 44488 | BG5: M | BJ5: 0484076270539 | BM5: 10 | BO5: 2 | BP5: N | BQ5: G | BR5: FALSE | BS5: 7751393525 | BT5: Chignahuapan | BW5: FALSE | BY5: FALSE | CD5: =+Table1[[#This Row],[Nombres]]&" "&Table1[[#This Row],[Ap_paterno]]&" "&Table1[[#This Row],[Ap_materno]] -> Marco Antonio Lozada Martinez
A6: 1899 | B6: Aguilera | C6: Hernandez | D6: Hipolito | E6: 24557 | F6: Nuevo León | G6: AUHH670326G84 | H6: Montes Dolomiticos | I6: Las Puentes | J6: San Nicolas de los Garza | K6: Monterrey | L6: 66460 | M6: Mexico | O6: TRUE | Q6: A | S6: Administrativo | T6: 8127553322 | X6: 4385678683-5 | Y6: Mexicana | Z6: AUHH670326HNLGRP01 | AA6: 2 | AB6: FALSE | AC6: 44382 | AD6: 44382 | AF6: 44782 | AG6: M | AH6: C | AI6: FALSE | AK6: FALSE | AL6: FALSE | AQ6: h.1899tusa@gmail.com | AU6: 5256783290819094 | AV6: Banamex | AW6: 42 | AX6: 38 | AY6: 28.0 | AZ6: XG | BA6: 0 | BB6: 403.95 | BC6: 0 | BD6: FALSE | BF6: 44789 | BG6: M | BJ6: 1817048222282 | BM6: 10 | BO6: 1 | BP6: N | BQ6: XG | BR6: FALSE | BS6: 8126583512 | BT6: Garcia | BW6: FALSE | BY6: FALSE | CD6: =+Table1[[#This Row],[Nombres]]&" "&Table1[[#This Row],[Ap_paterno]]&" "&Table1[[#This Row],[Ap_materno]] -> Hipolito Aguilera Hernandez
A7: 1766 | B7: Vivar | C7: Ramirez | D7: Marco Antonio | E7: 35691 | F7: México | G7: VIRM9709188S4 | H7: Achali Int A Mz 1, Lt 19 | I7: Artesanos | J7: Chimalhuacan | K7: México | L7: 56334 | M7: México | O7: FALSE | Q7: O | S7: Operativo | U7: 0000505-0000001 | X7: 1715977841-8 | Y7: Mexicana | Z7: VIRM970918HMCVMR08 | AA7: 1 | AB7: TRUE | AC7: 43948 | AD7: 43948 | AF7: 44022 | AG7: M | AH7: U | AI7: FALSE | AK7: TRUE | AL7: FALSE | AN7: Manejo | AO7: Rabon, torton | AP7: Manejo | AQ7: marco1997fde@gmail.com | AR7: 44022 | AU7: 5256783303422092 | AV7: Banamex | AW7: 0 | AX7: 0 | AY7: 0.0 | BA7: 0 | BB7: 247.99 | BC7: 0 | BD7: FALSE | BF7: 44100 | BG7: M | BJ7: 1953716026 | BK7: 1175104378486 | BM7: 10 | BO7: 1 | BP7: N | BR7: FALSE | BT7: Nezahualcoyotl | BW7: FALSE | BY7: FALSE | CD7: =+Table1[[#This Row],[Nombres]]&" "&Table1[[#This Row],[Ap_paterno]]&" "&Table1[[#This Row],[Ap_materno]] -> Marco Antonio Vivar Ramirez
A8: 1769 | B8: Rodriguez | C8: Gonzalez | D8: Daniel Israel | E8: 28244 | F8: Nuevo León | G8: ROGD770429G11 | H8: San Ignacio #211 | I8: Valle del Jarcel | J8: Monterrey | K8: Nuevo Leon | L8: 64000 | M8: Mexico | O8: TRUE | Q8: A | S8: Administrativo | T8: 8132482286 | U8: 0000505-0000001 | X8: 4394777648-0 | Y8: Mexicana | Z8: ROGD770429HNLDNN07 | AA8: 3 | AB8: TRUE | AC8: 43976 | AD8: 43976 | AF8: 44025 | AG8: M | AH8: C | AI8: FALSE | AK8: FALSE | AL8: FALSE | AN8: Vigilancia | AO8: Vigilancia | AP8: Vigilancia | AQ8: rodriguezgonzalezd77@gmail.com | AR8: 44025 | AU8: 5256783197081897 | AV8: Banamex | AW8: 0 | AX8: 32 | AY8: 0.0 | BA8: 0 | BB8: 242 | BC8: 0 | BD8: TRUE | BF8: 44028 | BG8: M | BJ8: 0441098727937 | BK8: 1658881762 | BM8: 10 | BO8: 2 | BP8: N | BR8: FALSE | BT8: Monterrey | BW8: FALSE | BY8: FALSE | CD8: =+Table1[[#This Row],[Nombres]]&" "&Table1[[#This Row],[Ap_paterno]]&" "&Table1[[#This Row],[Ap_materno]] -> Daniel Israel Rodriguez Gonzalez
A9: 1770 | B9: Cañas | C9: Hernandez | D9: Marco Antonio | E9: 32691 | F9: Chiapas | G9: CAHM890702D24 | H9: Primera Ave. 321 | I9: Satelite del Norte | J9: Monterrey | K9: Nuevo Leon | L9: 64000 | M9: México | O9: TRUE | Q9: A | S9: Administrativo | U9: 53603-01 14508255 | W9: 44829 | X9: 0518890860-1 | Y9: Mexicana | Z9: CAHM890702HCSXRR08 | AA9: 2 | AB9: TRUE | AC9: 43976 | AD9: 43976 | AG9: M | AH9: C | AI9: FALSE | AK9: FALSE | AL9: FALSE | AN9: Vigilancia | AO9: Vigilancia | AP9: Vigilancia | AQ9: canasmarco97@gmail.com | AU9: 5256784082658393 | AV9: Banamex | AW9: 36 | AX9: 36 | AY9: 6 | AZ9: 36 | BA9: 0 | BB9: 517.98 | BC9: 0 | BD9: TRUE | BF9: 44827 | BG9: M | BJ9: 1760081144961 | BK9: 1962741305 | BM9: 10 | BO9: 3 | BP9: N | BQ9: G | BR9: FALSE | BT9: Chiapa de Corzo | BW9: FALSE | BY9: FALSE | CD9: =+Table1[[#This Row],[Nombres]]&" "&Table1[[#This Row],[Ap_paterno]]&" "&Table1[[#This Row],[Ap_materno]] -> Marco Antonio Cañas Hernandez
A10: 1771 | B10: Mota | C10: Delgadillo | D10: Lorena | E10: 35000 | F10: Puebla | G10: MODL9510288W0 | H10: Granada No 2 | I10: Lomas del pedregal | J10: Apan | K10: Hidalgo | L10: 43917 | M10: México | N10: Ingenieria en Logistica | O10: TRUE | Q10: A | S10: Administrativo | T10: 7751572801 | U10: 0000505-0000001 | W10: 44012 | X10: 1516958884-3 | Y10: Mexicana | Z10: MODL951028MPLTLR09 | AA10: 2 | AB10: TRUE | AC10: 44001 | AD10: 44001 | AF10: 44026 | AG10: F | AH10: S | AI10: FALSE | AK10: TRUE | AL10: FALSE | AN10: Trafico y Rastreo | AO10: Trafico, Rastreo, servicio al cliente | AP10: Trafico | AQ10: lore28.il10@gmail.com | AR10: 44026 | AU10: 5256783340091298 | AV10: Banamex | AW10: CH | AX10: 0 | AY10: 0.0 | BA10: 0 | BB10: 445.24 | BC10: 3 | BD10: FALSE | BF10: 44048 | BG10: M | BJ10: 1892883214 | BK10: 0143096437935 | BM10: 10 | BO10: 5 | BP10: N | BR10: FALSE | BT10: Chignahuapan | BW10: FALSE | BY10: FALSE | CD10: =+Table1[[#This Row],[Nombres]]&" "&Table1[[#This Row],[Ap_paterno]]&" "&Table1[[#This Row],[Ap_materno]] -> Lorena Mota Delgadillo
A11: 1909 | B11: Hernandez | C11: Gomez | D11: Jose | E11: 25678 | F11: Hidalgo | G11: HEGJ700420MR5 | H11: Pachuca | I11: Pueblo Nuevo Barrio | J11: Pachuca de Soto | K11: Hidalgo | L11: 42181 | M11: Mexico | O11: TRUE | Q11: O | S11: Operativo | T11: 7711257753 | X11: 2089705298-9 | Y11: Mexicana | Z11: HEGJ700420HHGRMS07 | AA11: 1 | AB11: TRUE | AC11: 44392 | AD11: 44392 | AF11: 44504 | AG11: M | AH11: C | AI11: FALSE | AK11: TRUE | AL11: FALSE | AQ11: j.1909tusa@gmail.com | AR11: 44504 | AU11: 5256783591282893 | AV11: Banamex | AW11: 40 | AX11: 38 | AY11: 27.0 | AZ11: G | BA11: 0 | BB11: 545.07 | BC11: 0 | BD11: FALSE | BE11: 8112442233 | BF11: 44519 | BG11: M | BJ11: 0727008169396 | BM11: 10 | BO11: 2 | BP11: N | BQ11: XG | BR11: FALSE | BS11: 7712936258 | BT11: Huejutla de Reyes | BW11: FALSE | BY11: FALSE | CD11: =+Table1[[#This Row],[Nombres]]&" "&Table1[[#This Row],[Ap_paterno]]&" "&Table1[[#This Row],[Ap_materno]] -> Jose Hernandez Gomez
A12: 1767 | B12: Moreno | C12: Perez | D12: Aldo Alexis BAJA | E12: 34465 | F12: Tlaxcala | G12: MOPA940511CY2 | H12: Apizaco SN | I12: San Miguel Xolco | J12: Otumba | K12: México | L12: 55900 | M12: México | O12: TRUE | Q12: O | S12: Operativo | X12: 9413948592-7 | Y12: Mexicana | Z12: MOPA940511HTLRRL04 | AA12: 1 | AB12: TRUE | AC12: 43948 | AD12: 43948 | AF12: 43950 | AG12: M | AH12: U | AI12: FALSE | AK12: FALSE | AL12: FALSE | AR12: 43950 | AU12: 5256783292521599 | AV12: Banamex | AW12: 0 | AX12: 0 | AY12: 0.0 | BA12: 0 | BB12: 130.48 | BC12: 0 | BD12: FALSE | BF12: 44264 | BG12: M | BJ12: 3891132358263 | BK12: 1315052100107 | BM12: 10 | BO12: 3 | BP12: N | BR12: FALSE | BT12: Calpulalpan | BW12: FALSE | BY12: FALSE | CD12: =+Table1[[#This Row],[Nombres]]&" "&Table1[[#This Row],[Ap_paterno]]&" "&Table1[[#This Row],[Ap_materno]] -> Aldo Alexis BAJA Moreno Perez
A13: 1773 | B13: Espejel | C13: Alonso | D13: Emigdio | E13: 26959 | F13: Tlaxcala | G13: EEAE731022DU1 | H13: Av. Netzahualcoyotl Sur No 6 | I13: El Mirador | J13: Calpulalpan | K13: Tlaxcala | L13: 90204 | M13: México | O13: TRUE | Q13: O | S13: Operativo | T13: 7491010492 | U13: 12322506 | W13: 44829 | X13: 6191731192-2 | Y13: Mexicana | Z13: EEAE731022HTLSLM06 | AA13: 1 | AB13: TRUE | AC13: 44005 | AD13: 44005 | AF13: 45428 | AG13: M | AH13: U | AI13: FALSE | AK13: FALSE | AL13: FALSE | AM13: Marisol Aguirre Conyuge 2411101703 Luis Espejel Hno 5531503931 Monserrat Espejel hija 7491142177 | AN13: Manejo | AO13: Tractocamion | AP13: Manejo | AQ13: espejelalonsoemigdio@gmail.com | AU13: 5256784052415998 | AV13: Banamex | AW13: 44 | AX13: 38 | AY13: 26.0 | AZ13: 0 | BA13: 0 | BB13: 345.97 | BC13: 3 | BD13: FALSE | BF13: 45593 | BG13: M | BJ13: 1571339469 | BK13: 0088014061996 | BM13: 10 | BO13: 2 | BP13: N | BQ13: CH | BR13: TRUE | BS13: 74911142177 | BT13: Calpulalpan | BU13: 44852 | BV13: 45410 | BW13: FALSE | BY13: FALSE | CD13: =+Table1[[#This Row],[Nombres]]&" "&Table1[[#This Row],[Ap_paterno]]&" "&Table1[[#This Row],[Ap_materno]] -> Emigdio Espejel Alonso
A14: 1772 | B14: Barrios | C14: Gonzalez | D14: Gerardo | E14: 27296 | F14: Puebla | G14: BAGG740924244 | H14: Luis Donaldo Colosio 4 | I14: San Juan | J14: Huauchinango | K14: Puebla | L14: 73160 | M14: Mexico | O14: TRUE | Q14: O | S14: Operativo | U14: 004-0000384386-00 | X14: 0316740149-0 | Y14: Mexicana | Z14: BAGG740924HPLRNR01 | AA14: 1 | AB14: TRUE | AC14: 44005 | AD14: 44005 | AF14: 44280 | AG14: M | AH14: C | AI14: FALSE | AK14: TRUE | AL14: FALSE | AN14: Manejo | AO14: Manejo | AP14: Manejo | AQ14: gerabarrios995@gmail.com | AR14: 44280 | AU14: 5579070119195256 | AV14: Banamex | AW14: 0 | AX14: 0 | AY14: 0.0 | BA14: 0 | BB14: 308.3 | BC14: 3 | BD14: TRUE | BE14: 7711278215 | BF14: 44284 | BG14: M | BJ14: 0605056916281 | BK14: 1877236260 | BM14: 10 | BO14: 1 | BP14: N | BR14: FALSE | BT14: Puebla | BW14: FALSE | BY14: FALSE | CD14: =+Table1[[#This Row],[Nombres]]&" "&Table1[[#This Row],[Ap_paterno]]&" "&Table1[[#This Row],[Ap_materno]] -> Gerardo Barrios Gonzalez
A15: 1774 | B15: Romo | C15: Alonso | D15: Abraham | E15: 33226 | F15: Hidalgo | G15: ROAA901219SC7 | H15: Centeno No 117 | I15: Lomas de Nopalapa | J15: Pachuca | K15: Hidalgo | L15: 42186 | M15: México | O15: TRUE | Q15: O | S15: Operativo | T15: 7711850966 | U15: 0000505-0000001 | X15: 1310901967-2 | Y15: Mexicana | Z15: ROAA901219HHGMLB02 | AA15: 1 | AB15: TRUE | AC15: 44005 | AD15: 44005 | AF15: 44022 | AG15: M | AH15: U | AI15: FALSE | AK15: FALSE | AL15: FALSE | AN15: Manejo | AO15: Revolvedoras, tractos | AP15: Manejo | AQ15: romofernando875@gmail.com | AR15: 44022 | AU15: 5256783094097897 | AV15: Banamex | AW15: 0 | AX15: 0 | AY15: 0.0 | BA15: 0 | BB15: 130.48 | BC15: 0 | BD15: FALSE | BF15: 44028 | BG15: M | BJ15: 1813046076 | BK15: 0740084007977 | BM15: 10 | BO15: 2 | BP15: N | BR15: FALSE | BT15: Pachuca de Soto | BW15: FALSE | BY15: FALSE | CD15: =+Table1[[#This Row],[Nombres]]&" "&Table1[[#This Row],[Ap_paterno]]&" "&Table1[[#This Row],[Ap_materno]] -> Abraham Romo Alonso
A16: 1775 | B16: Morales | C16: Hernandez | D16: Juan Jose | E16: 33202 | F16: Veracruz | G16: MOHJ9011254M1 | H16: Independencia No. 2 | I16: Centro | J16: Acajete | K16: Veracruz | L16: 45180 | M16: Mexico | O16: FALSE | Q16: O | S16: Operativo | U16: 0000505-0000001 | X16: 6509902983-0 | Y16: Mexicana | Z16: MOHJ901125HVZRRN01 | AA16: 1 | AB16: TRUE | AC16: 44005 | AD16: 44005 | AF16: 44027 | AG16: M | AH16: U | AI16: FALSE | AK16: TRUE | AL16: FALSE | AN16: Manejar | AO16: Manejar | AP16: Manejar | AQ16: fahrenheit.morales@gmail.com | AR16: 44027 | AU16: 5256783340091199 | AV16: Banamex | AW16: 0 | AX16: 0 | AY16: 0.0 | BA16: 0 | BB16: 130.48 | BC16: 3 | BD16: TRUE | BF16: 44028 | BG16: M | BJ16: 2993083217806 | BK16: 1509943889 | BM16: 10 | BO16: 3 | BP16: N | BR16: FALSE | BT16: Xalapa | BW16: FALSE | BY16: FALSE | CD16: =+Table1[[#This Row],[Nombres]]&" "&Table1[[#This Row],[Ap_paterno]]&" "&Table1[[#This Row],[Ap_materno]] -> Juan Jose Morales Hernandez
A17: 1776 | B17: Arellano | C17: Ramirez | D17: Francisco | E17: 29770 | F17: Puebla | G17: AERF810703L98 | H17: Sonora #16B | I17: La Conchita | J17: Apan | K17: Hidalgo | L17: 43900 | M17: Mexico | O17: TRUE | Q17: O | S17: Operativo | U17: 0000505-0000001 | X17: 7201810717-6 | Y17: Mexicana | Z17: AERF810703HPLRMR04 | AA17: 1 | AB17: TRUE | AC17: 44021 | AD17: 44021 | AF17: 44096 | AG17: M | AH17: C | AI17: FALSE | AK17: FALSE | AL17: FALSE | AN17: Menejo | AO17: Mnejo | AP17: Manejo | AQ17: f.1776tusa@gmail.com | AR17: 44096 | AU17: 5256783273291691 | AV17: Banamex | AW17: 0 | AX17: 0 | AY17: 0.0 | BA17: 0 | BB17: 302.2 | BC17: 3 | BD17: FALSE | BF17: 44102 | BG17: M | BJ17: 0128010273166 | BK17: 1833800191 | BM17: 10 | BO17: 3 | BP17: N | BR17: FALSE | BT17: Puebla | BW17: FALSE | BY17: FALSE | CD17: =+Table1[[#This Row],[Nombres]]&" "&Table1[[#This Row],[Ap_paterno]]&" "&Table1[[#This Row],[Ap_materno]] -> Francisco Arellano Ramirez
A18: 1777 | B18: Santillan | C18: Montes | D18: Evaristo | E18: 28059 | G18: SAME7610267E9 | H18: Simon Bolivar S/N | I18: Barrio los Laureles | J18: Hueypoxtla | K18: México | L18: 55670 | M18: México | O18: FALSE | Q18: O | S18: Operativo | U18: 0000505-0000001 | W18: 44027 | X18: 9499760642-4 | Y18: Mexicana | Z18: SAME761026HMCNNV09 | AA18: 1 | AB18: TRUE | AC18: 44021 | AD18: 44021 | AF18: 44096 | AG18: M | AH18: C | AI18: FALSE | AK18: FALSE | AL18: FALSE | AQ18: e.1777tusa@gmail.com | AR18: 44096 | AU18: 5256783340625491 | AV18: Banamex | AW18: 0 | AX18: 0 | AY18: 0.0 | BA18: 0 | BB18: 280.12 | BC18: 3 | BD18: FALSE | BF18: 44102 | BG18: M | BJ18: 1981047215807 | BK18: 0000065522494 | BM18: 10 | BO18: 2 | BP18: N | BR18: FALSE | BW18: FALSE | BY18: FALSE | CD18: =+Table1[[#This Row],[Nombres]]&" "&Table1[[#This Row],[Ap_paterno]]&" "&Table1[[#This Row],[Ap_materno]] -> Evaristo Santillan Montes
A19: 1778 | B19: Lopantzi | C19: Flores | D19: Brigido | E19: 26580 | F19: Tlaxcala | G19: LOFB721008GD5 | H19: San Jose #22 | I19: Aztatla | J19: Aztatla | K19: Tlaxcala | L19: 90670 | M19: Mexico | O19: TRUE | Q19: O | S19: Operativo | U19: 004-0000384386-00 | X19: 0216720171-0 | Y19: Mexicana | Z19: LOFB721008HTLPLR04 | AA19: 1 | AB19: TRUE | AC19: 44021 | AD19: 44021 | AF19: 44293 | AG19: M | AH19: C | AI19: FALSE | AK19: TRUE | AL19: FALSE | AM19: Numero personal 2461229788 | AN19: Manejo | AO19: Manejo | AP19: Manejo | AQ19: b.1778tusa@gmail.com | AR19: 44293 | AU19: 5256783340109199 | AV19: Banamex | AW19: 0 | AX19: 0 | AY19: 0.0 | BA19: 0 | BB19: 365.07 | BC19: 3 | BD19: FALSE | BE19: 7711895521 | BF19: 44293 | BG19: M | BJ19: 0281010070631 | BK19: 1418242550 | BM19: 10 | BO19: 2 | BP19: N | BR19: FALSE | BT19: Tlaxcala | BW19: FALSE | BY19: FALSE | CD19: =+Table1[[#This Row],[Nombres]]&" "&Table1[[#This Row],[Ap_paterno]]&" "&Table1[[#This Row],[Ap_materno]] -> Brigido Lopantzi Flores
A20: 1780 | B20: Avelar | C20: Sandoval | D20: Pedro | E20: 28637 | F20: México | G20: AESP780527421 | H20: Cda. 2da. de Rosendo Arnaiz 4 | I20: Rosendo Arnaiz | J20: San Martin de las Piramides | K20: Estado de México | L20: 55850 | M20: Mexico | N20: na | O20: TRUE | Q20: O | S20: Operativo | U20: 004-0000384386-00 | X20: 9400780681-6 | Y20: Mexicana | Z20: AESP780527HMCVND05 | AA20: 1 | AB20: TRUE | AC20: 44025 | AD20: 44025 | AF20: 44249 | AG20: M | AH20: U | AI20: FALSE | AK20: TRUE | AL20: FALSE | AN20: Manejar | AO20: Conduccion | AP20: Mecanica | AQ20: avelarpedro53@gmail.com | AR20: 44249 | AU20: 5256783396126196 | AV20: Banamex | AW20: 42 | AX20: 42 | AY20: 0.0 | AZ20: 42 | BA20: 0 | BB20: 320.71 | BC20: 4 | BD20: FALSE | BE20: 7714036618 | BF20: 44250 | BG20: M | BJ20: 4108015579652 | BK20: 1488984361 | BM20: 10 | BO20: 2 | BP20: N | BQ20: XG | BR20: FALSE | BT20: San Martin de las Piramides | BW20: FALSE | BY20: FALSE | CD20: =+Table1[[#This Row],[Nombres]]&" "&Table1[[#This Row],[Ap_paterno]]&" "&Table1[[#This Row],[Ap_materno]] -> Pedro Avelar Sandoval
A21: 1783 | B21: Dominguez | C21: Olvera | D21: Martin | E21: 21580 | F21: Hidalgo | G21: DOOM590130MM9 | H21: Letra O Nº 9 | I21: Abecedario | J21: Sahagun | K21: Hidalgo | L21: 43990 | M21: México | O21: TRUE | Q21: A | S21: Administrativo | T21: 8112445652 | U21: 004-0000384386-00 | X21: 1378590571-5 | Y21: Mexicana | Z21: DOOM590130HHGMLR04 | AA21: 2 | AB21: FALSE | AC21: 44037 | AD21: 44037 | AF21: 44225 | AG21: M | AH21: C | AI21: FALSE | AK21: FALSE | AL21: FALSE | AQ21: martin56dominguezz@gmail.com | AR21: 44225 | AU21: 5256782591837094 | AV21: Banamex | AW21: 0 | AX21: 0 | AY21: 0.0 | BA21: 0 | BB21: 333.29 | BC21: 4 | BD21: FALSE | BE21: 8115387710 | BF21: 44265 | BG21: M | BI21: 7711895511 | BJ21: 1478024644 | BK21: 1211018459541 | BM21: 10 | BO21: 1 | BP21: N | BR21: FALSE | BT21: Tepeapulco | BW21: FALSE | BY21: FALSE | CD21: =+Table1[[#This Row],[Nombres]]&" "&Table1[[#This Row],[Ap_paterno]]&" "&Table1[[#This Row],[Ap_materno]] -> Martin Dominguez Olvera
A22: 1768 | B22: Rosas | C22: Esteban | D22: Martin Eduardo | E22: 32559 | F22: Hidalgo | G22: ROEM890220AF1 | H22: Av. Mexico | I22: Benito Juarez | J22: Sahagun | K22: Hidalgo | L22: 43994 | M22: Mexico | O22: FALSE | Q22: O | S22: Operativo | U22: 0000505-0000001 | X22: 1307893400-0 | Y22: Mexicana | Z22: ROEM890220HHGSSR00 | AA22: 1 | AB22: TRUE | AC22: 43949 | AD22: 43949 | AF22: 44102 | AG22: M | AH22: C | AI22: FALSE | AK22: TRUE | AL22: FALSE | AQ22: m.1768tusa@gmail.com | AR22: 44102 | AU22: 5256782097794997 | AV22: Banamex | AW22: 0 | AX22: 0 | AY22: 0.0 | BA22: 0 | BB22: 311.82 | BC22: 0 | BD22: FALSE | BF22: 44110 | BG22: M | BJ22: 1814780560 | BK22: 1221078045139 | BM22: 10 | BO22: 1 | BP22: N | BR22: FALSE | BT22: Tepeapulco | BW22: FALSE | BY22: FALSE | CD22: =+Table1[[#This Row],[Nombres]]&" "&Table1[[#This Row],[Ap_paterno]]&" "&Table1[[#This Row],[Ap_materno]] -> Martin Eduardo Rosas Esteban
A23: 1779 | B23: Lopez | C23: Islas | D23: Amado | E23: 25208 | F23: México | G23: LOIA690105GH6 | H23: Lirios No 131 | I23: La Rosa | J23: El Susto, Singuilucan | K23: Hidalgo | L23: 43790 | M23: Mexico | O23: TRUE | Q23: O | S23: Operativo | W23: 44027 | X23: 0186691822-8 | Y23: Mexicana | Z23: LOIA690105HDFPSM03 | AA23: 1 | AB23: TRUE | AC23: 44022 | AF23: 44023 | AG23: M | AH23: C | AI23: FALSE | AK23: TRUE | AL23: FALSE | AN23: Manejo | AO23: Manejo | AP23: Manejo | AW23: 0 | AX23: 0 | AY23: 0.0 | BA23: 0 | BB23: 130.48 | BC23: 0 | BD23: FALSE | BF23: 44047 | BG23: M | BJ23: 1123035160674 | BK23: 1479318407 | BM23: 10 | BO23: 1 | BP23: N | BR23: FALSE | BT23: Chapultepec | BW23: FALSE | BY23: FALSE | CD23: =+Table1[[#This Row],[Nombres]]&" "&Table1[[#This Row],[Ap_paterno]]&" "&Table1[[#This Row],[Ap_materno]] -> Amado Lopez Islas
A24: 1785 | B24: Zarate | C24: De Lucio | D24: Agustin | E24: 28638 | F24: Hidalgo | G24: ZALA780528HM8 | H24: Belizario Dominguez No 6 | I24: Jaltepec | J24: Axapusco | K24: México | L24: 55965 | M24: México | O24: TRUE | Q24: O | S24: Operativo | U24: 0000505-0000001 | W24: 44042 | X24: 1396782571-5 | Y24: Mexicana | Z24: ZALA780528HHGRCG00 | AA24: 1 | AB24: TRUE | AC24: 44042 | AD24: 44042 | AF24: 44114 | AG24: M | AH24: C | AI24: FALSE | AK24: FALSE | AL24: FALSE | AQ24: a.1785tus@gmail.com | AR24: 44114 | AU24: 5256783340106492 | AV24: Banamex | AW24: 34 | AX24: 32 | AY24: 0.0 | BA24: 0 | BB24: 171.27 | BC24: 4 | BD24: FALSE | BF24: 44126 | BG24: M | BJ24: 1867915249 | BK24: 0485052700288 | BM24: 10 | BO24: 2 | BP24: N | BQ24: M | BR24: FALSE | BT24: Tepeapulco | BW24: FALSE | BY24: FALSE | CD24: =+Table1[[#This Row],[Nombres]]&" "&Table1[[#This Row],[Ap_paterno]]&" "&Table1[[#This Row],[Ap_materno]] -> Agustin Zarate De Lucio
A25: 1787 | B25: Lopez | C25: Pastrana | D25: Jorge | E25: 29446 | F25: Hidalgo | G25: LOPJ800813CJ5 | H25: Rosendo Flores No 54 | I25: Centro | J25: Emiliano Zapata | K25: Hidalo | L25: 43960 | M25: México | O25: TRUE | Q25: O | S25: Operativo | U25: 0000505-0000001 | W25: 44042 | X25: 1399801646-6 | Y25: Mexicana | Z25: LOPJ800813HHGPSR08 | AA25: 1 | AB25: TRUE | AC25: 44042 | AD25: 44042 | AF25: 44081 | AG25: M | AH25: C | AI25: FALSE | AK25: TRUE | AL25: FALSE | AQ25: j.1787tusa@gmail.com | AR25: 44081 | AU25: 5256782646441496 | AV25: Banamex | AW25: 40 | AX25: 32 | AY25: 0.0 | BA25: 0 | BB25: 208.47 | BC25: 4 | BD25: FALSE | BF25: 44088 | BG25: M | BJ25: 1143369313 | BK25: 0352071577098 | BM25: 10 | BO25: 3 | BP25: N | BQ25: G | BR25: FALSE | BT25: Tepeapulco | BW25: FALSE | BY25: FALSE | CD25: =+Table1[[#This Row],[Nombres]]&" "&Table1[[#This Row],[Ap_paterno]]&" "&Table1[[#This Row],[Ap_materno]] -> Jorge Lopez Pastrana
A26: 1788 | B26: Ortiz | C26: Urbina | D26: Jose Saul | E26: 34927 | F26: Nuevo León | G26: OIUS950816HNLRRL02 | H26: Alvaro Obregon No 324 | I26: La Loma, Zona Centro | J26: Mina | K26: Nuevo Leon | L26: 65100 | M26: México | N26: Tecnico en informatica | O26: FALSE | Q26: A | S26: Administrativo | U26: 0000505-0000001 | W26: 44043 | X26: 4313951591-0 | Y26: Mexicana | Z26: OIUS950816SS3 | AA26: 2 | AB26: TRUE | AC26: 44043 | AD26: 44043 | AF26: 44050 | AG26: M | AH26: C | AI26: FALSE | AK26: FALSE | AL26: FALSE | AO26: Control de patio | AR26: 44050 | AU26: 5256783352741095 | AV26: Banamex | AW26: 0 | AX26: 0 | AY26: 0.0 | BA26: 0 | BB26: 350.14 | BC26: 4 | BD26: FALSE | BF26: 44125 | BG26: M | BJ26: 2408135009391 | BK26: 1319122606533 | BM26: 10 | BO26: 3 | BP26: N | BR26: FALSE | BT26: San Nicolas de los Garza | BW26: FALSE | BY26: FALSE | CD26: =+Table1[[#This Row],[Nombres]]&" "&Table1[[#This Row],[Ap_paterno]]&" "&Table1[[#This Row],[Ap_materno]] -> Jose Saul Ortiz Urbina
A27: 1793 | B27: Beltran | C27: Nolasco | D27: Jose Pedro | E27: 33175 | F27: Hidalgo | G27: BENP901029ND3 | H27: Allende 14B | I27: Santa Barbara | J27: Santa Barbara | K27: Hidalgo | L27: 43961 | M27: México | O27: TRUE | Q27: O | S27: Operativo | T27: 7751892546 | X27: 1310902883-0 | Y27: Mexicana | Z27: BENP901029HHGLLD16 | AA27: 1 | AB27: TRUE | AC27: 44053 | AD27: 44053 | AF27: 44095 | AG27: M | AH27: U | AI27: FALSE | AK27: TRUE | AL27: FALSE | AN27: Manejo | AO27: Manejo | AP27: Manejo | AQ27: pedro291090@gmail.com | AR27: 44095 | AU27: 5256783037004398 | AV27: Banamex | AW27: 32 | AX27: 38 | AY27: 0.0 | BA27: 0 | BB27: 257.58 | BC27: 4 | BD27: FALSE | BF27: 44102 | BG27: M | BJ27: 0357082701881 | BK27: 2012343542 | BM27: 10 | BO27: 2 | BP27: N | BQ27: M | BR27: FALSE | BT27: Apan | BW27: FALSE | BY27: FALSE | CD27: =+Table1[[#This Row],[Nombres]]&" "&Table1[[#This Row],[Ap_paterno]]&" "&Table1[[#This Row],[Ap_materno]] -> Jose Pedro Beltran Nolasco
A28: 1790 | B28: Villalpa | C28: Islas | D28: Jesus Manuel BAJA 2 | E28: 30578 | F28: Hidalgo | G28: VIIJ830919K72 | H28: Calle 1 M24 L29 | I28: Palmillas | J28: Sahagún | K28: Hidalgo | L28: 43998 | M28: México | O28: FALSE | Q28: O | S28: Operativo | T28: 5532051626 | U28: 53 | W28: 44829 | X28: 0217838917-3 | Y28: Mexicana | Z28: VIIJ830919HHGLSS05 | AA28: 1 | AB28: TRUE | AC28: 44053 | AD28: 44053 | AF28: 45124 | AG28: M | AH28: C | AI28: FALSE | AK28: FALSE | AL28: FALSE | AM28: 7713471060 telefono personal | AO28: Autobus, tactos | AQ28: villalpaislasjesus@gmail.com | AR28: 45124 | AU28: 5579100241407798 | AV28: Banamex | AW28: 40 | AX28: 34 | AY28: 0.0 | BA28: 0 | BB28: 396.15 | BC28: 4 | BD28: FALSE | BF28: 45430 | BG28: M | BJ28: 1470200046 | BK28: 1209030916099 | BM28: 10 | BO28: 2 | BP28: N | BR28: TRUE | BS28: 7757068741 | BT28: Tepeapulco | BU28: 44856 | BW28: FALSE | BY28: FALSE | CD28: =+Table1[[#This Row],[Nombres]]&" "&Table1[[#This Row],[Ap_paterno]]&" "&Table1[[#This Row],[Ap_materno]] -> Jesus Manuel BAJA 2 Villalpa Islas
A29: 1791 | B29: Bermudez | C29: Merida | D29: Efrain | E29: 31300 | F29: Hidalgo | G29: BEME850910VC6 | H29: Josefa Ortiz de Dominguez No 16 A | I29: Irolo | J29: Irolo | K29: Hidalgo | L29: 43991 | M29: México | O29: TRUE | Q29: O | S29: Operativo | T29: 7919136203 | W29: 44058 | X29: 1302850426-7 | Y29: Mexicana | Z29: BEME850910HHGRRF08 | AA29: 1 | AB29: TRUE | AC29: 44053 | AD29: 44053 | AF29: 44105 | AG29: M | AH29: U | AI29: FALSE | AK29: FALSE | AL29: FALSE | AN29: Manejo | AO29: Conduccion de unidades en general | AP29: Manejo | AQ29: e.1791tusa@gmail.com | AR29: 44105 | AU29: 5256783377479499 | AV29: Banamex | AW29: 0 | AX29: 0 | AY29: 0.0 | BA29: 0 | BB29: 293.4 | BC29: 4 | BD29: FALSE | BF29: 44125 | BG29: M | BJ29: 1586481227 | BK29: 1228066151383 | BM29: 10 | BO29: 2 | BP29: N | BR29: FALSE | BT29: Tepeapulco | BW29: FALSE | BY29: FALSE | CD29: =+Table1[[#This Row],[Nombres]]&" "&Table1[[#This Row],[Ap_paterno]]&" "&Table1[[#This Row],[Ap_materno]] -> Efrain Bermudez Merida
A30: 1796 | B30: Galindo | C30: Calderon | D30: Carlos | E30: 27837 | F30: México | G30: GACC760318I11 | H30: Jenufa Mz 102 L22 | I30: Miguel Hidalgo | J30: Tlahuac | K30: D.F. | L30: 13200 | M30: México | O30: TRUE | Q30: O | S30: Operativo | T30: 5570324890 | W30: 44058 | X30: 4296761627-9 | Y30: Mexicana | Z30: GACC760318HDFLLR09 | AA30: 1 | AB30: FALSE | AC30: 44053 | AD30: 44053 | AF30: 44088 | AG30: M | AH30: C | AI30: FALSE | AK30: FALSE | AL30: FALSE | AO30: tricuerna | AQ30: charlie187641@gmail.com | AR30: 44088 | AU30: 5256783345237193 | AV30: Banamex | AW30: 0 | AX30: 0 | AY30: 0.0 | BA30: 0 | BB30: 287.93 | BC30: 0 | BD30: FALSE | BF30: 44095 | BG30: M | BJ30: 1740545224 | BK30: 3678041209624 | BM30: 10 | BO30: 2 | BP30: N | BR30: TRUE | BT30: Aculco | BW30: FALSE | BY30: FALSE | CD30: =+Table1[[#This Row],[Nombres]]&" "&Table1[[#This Row],[Ap_paterno]]&" "&Table1[[#This Row],[Ap_materno]] -> Carlos Galindo Calderon
A31: 1797 | B31: Lopez | C31: Ortega | D31: Beatriz | E31: 28824 | F31: Hidalgo | G31: LOOB7811303E5 | H31: Aldama No. 10 | I31: Centro | J31: Tlanalapa | K31: Hidalgo | L31: 43930 | M31: México | N31: Administracion de la calidad | O31: TRUE | Q31: A | S31: Administrativo | T31: 7711195439 | U31: 24 | W31: 44829 | X31: 13-03-78-0821-2 | Y31: Mexicana | Z31: LOOB781130MHGPRT04 | AA31: 2 | AB31: TRUE | AC31: 44060 | AD31: 44060 | AF31: 45030 | AG31: F | AH31: C | AI31: FALSE | AK31: FALSE | AL31: FALSE | AR31: 45030 | AU31: 5256781821733198 | AV31: Banamex | AW31: 0 | AX31: 0 | AY31: 0.0 | BA31: 0 | BB31: 545.89 | BC31: 0 | BD31: FALSE | BF31: 45042 | BG31: M | BJ31: 0000102525337 | BK31: 1397071423316 | BM31: 10 | BO31: 6 | BP31: N | BR31: FALSE | BS31: 7711293467 | BT31: Tepeapulco | BW31: FALSE | BY31: FALSE | CD31: =+Table1[[#This Row],[Nombres]]&" "&Table1[[#This Row],[Ap_paterno]]&" "&Table1[[#This Row],[Ap_materno]] -> Beatriz Lopez Ortega
A32: 1911 | B32: Sarabia | C32: Franco | D32: Luis Roberto | E32: 36086 | F32: Hidalgo | G32: SAFL981018F13 | H32: Felipe Angeles | I32: Barrio Negro | J32: Irolo | K32: Hidalgo | L32: 43991 | M32: Mexico | O32: TRUE | Q32: A | S32: Administrativo | T32: 7713922624 | X32: 1311980012-9 | Y32: Mexicana | Z32: SAFL981018HHGRRS09 | AA32: 2 | AB32: FALSE | AC32: 44403 | AD32: 44403 | AF32: 44522 | AG32: M | AH32: S | AI32: FALSE | AK32: FALSE | AL32: FALSE | AQ32: l.1911tusa@gmail.com | AR32: 44522 | AU32: 5256783613742890 | AV32: Banamex | AW32: 32 | AX32: 32 | AY32: 28.0 | AZ32: G | BA32: 0 | BB32: 424.13 | BC32: 0 | BD32: FALSE | BE32: 7712199121 | BF32: 44522 | BG32: M | BJ32: 1228118312273 | BM32: 10 | BO32: 5 | BP32: N | BQ32: M | BR32: FALSE | BS32: 7714204514 | BT32: Tepeapulco | BW32: FALSE | BY32: FALSE | CD32: =+Table1[[#This Row],[Nombres]]&" "&Table1[[#This Row],[Ap_paterno]]&" "&Table1[[#This Row],[Ap_materno]] -> Luis Roberto Sarabia Franco
A33: 1565 | B33: Lopez | C33: Hernandez | D33: Aurora Elizabeth | E33: 28302 | F33: Nuevo León | G33: LOHA7706269G3 | H33: Olmo No 130 | I33: Privada del Sauce, Sec Ebano | J33: Gral. Escobedo | K33: Nuevo Leon | L33: 66050 | M33: México | O33: FALSE | Q33: A | S33: Administrativo | U33: 0000503 0000002 | W33: 43158 | X33: 4300772762-1 | Y33: Mexicana | Z33: LOHA770626MNLPRR07 | AA33: 2 | AB33: TRUE | AC33: 43158 | AD33: 43158 | AF33: 43269 | AG33: F | AH33: C | AI33: FALSE | AK33: TRUE | AL33: TRUE | AN33: Compras, ventas, trafico | AO33: Compras, Responsable de tienda, Jefe de trafico | AP33: Trafico | AQ33: alope1522cy@gmail.com | AR33: 43279 | AU33: 5256782627440491 | AV33: Banamex | AW33: 0 | AX33: 0 | AY33: 0.0 | BA33: 1 | BB33: 423 | BC33: 1 | BD33: FALSE | BF33: 43315 | BG33: M | BJ33: 1582306991 | BK33: 0442062320301 | BM33: 10 | BO33: 2 | BP33: N | BT33: San Nicolas de los Garza | BW33: FALSE | BY33: FALSE | CD33: =+Table1[[#This Row],[Nombres]]&" "&Table1[[#This Row],[Ap_paterno]]&" "&Table1[[#This Row],[Ap_materno]] -> Aurora Elizabeth Lopez Hernandez
A34: 1564 | B34: Juarez | C34: Nieves | D34: Florencio Ivan | E34: 30172 | F34: Tlaxcala | G34: JUNF820809633 | H34: Magdalena de Quino No 3 | I34: Alfonso Espejel | J34: Calpulalpan | K34: Tlaxcala | L34: 90208 | M34: México | O34: TRUE | Q34: O | S34: Operativo | U34: 0000503 0000002 | V34: 000000000 | W34: 43144 | X34: 6104820468-1 | Y34: Mexicana | Z34: JUNF820809HTLRVL08 | AA34: 1 | AB34: TRUE | AC34: 43144 | AD34: 43144 | AF34: 43325 | AG34: M | AH34: C | AI34: FALSE | AK34: TRUE | AL34: TRUE | AN34: Manejo | AO34: Manejo de unidades de 48", full | AP34: Manejo | AQ34: ivan_jr24ju@hotmail.com | AR34: 43325 | AU34: 5256781751750998 | AV34: Banamex | AW34: 40 | AX34: 36 | AY34: 27.0 | AZ34: XL | BA34: 1 | BB34: 234.99 | BC34: 1 | BD34: FALSE | BF34: 43399 | BG34: M | BJ34: 1326055147 | BK34: 0078011381968 | BM34: 10 | BO34: 2 | BP34: N | BT34: Calpulalpan | BW34: FALSE | BY34: FALSE | CD34: =+Table1[[#This Row],[Nombres]]&" "&Table1[[#This Row],[Ap_paterno]]&" "&Table1[[#This Row],[Ap_materno]] -> Florencio Ivan Juarez Nieves
A35: 1563 | B35: Avila | C35: Aguirre | D35: Juan Antonio | E35: 28456 | F35: México | G35: AIAJ771127BK2 | H35: C. de la Gloria No 6 | I35: Loc. San Juanico | J35: Acolman | K35: México | L35: 55871 | M35: México | O35: TRUE | Q35: O | S35: Operativo | T35: 5565314118 | U35: 00000504 | V35: C-2694262 | W35: 43144 | X35: 9495772125-4 | Y35: Mexicana | Z35: AIAJ771127HMCVGN09 | AA35: 1 | AB35: TRUE | AC35: 43144 | AD35: 43144 | AF35: 43887 | AG35: M | AH35: U | AI35: FALSE | AK35: TRUE | AL35: TRUE | AN35: Manejo | AO35: Manejo | AP35: Manejo | AQ35: j.1563tusa@gmail.com | AR35: 43887 | AU35: 5256782352152295 | AV35: Banamex | AW35: 34 | AX35: 34 | AY35: 0.0 | BA35: 1 | BB35: 264.36 | BC35: 1 | BD35: FALSE | BF35: 43892 | BG35: M | BJ35: 1181201097 | BK35: 0037047358906 | BM35: 10 | BO35: 2 | BP35: N | BR35: FALSE | BT35: Aculco | BW35: FALSE | BY35: FALSE | CD35: =+Table1[[#This Row],[Nombres]]&" "&Table1[[#This Row],[Ap_paterno]]&" "&Table1[[#This Row],[Ap_materno]] -> Juan Antonio Avila Aguirre
A36: 1562 | B36: Tenopala | C36: Hernandez | D36: Gerardo Guadalupe | E36: 22192 | F36: Tlaxcala | G36: TEHG601003TY6 | H36: Isidro Candida Galvan Edif 49 Depto 7 | I36: U Hab Infonavit | J36: Calpulalpan | K36: Tlaxcala | L36: 90203 | M36: México | O36: TRUE | Q36: O | S36: Operativo | T36: 7491027818 | U36: 004-0000384386-00 | V36: b-1439279 | W36: 43144 | X36: 1380601678-1 | Y36: Mexicana | Z36: TEHG601003HTLNRR04 | AA36: 1 | AB36: TRUE | AC36: 43144 | AD36: 43144 | AF36: 44424 | AG36: M | AH36: C | AI36: FALSE | AK36: TRUE | AL36: TRUE | AM36: Se realiza reingreso por motivo de proyecto Lazaro Cardenas 15 al 20 de mayo de 2022, | AN36: Manejo | AO36: Manejo de camiones, pipas de combustible y de volteo | AP36: Manejo | AQ36: g.1562tusa@gmail.com | AR36: 44424 | AU36: 5256782567084994 | AV36: Banamex | AW36: 36 | AX36: 34 | AY36: 0.0 | BA36: 1 | BB36: 741.06 | BC36: 1 | BD36: FALSE | BF36: 44704 | BG36: M | BJ36: 1586541857 | BK36: 0082050147524 | BM36: 10 | BO36: 2 | BP36: N | BR36: FALSE | BS36: 7711470457 | BT36: Calpulalpan | BW36: FALSE | BY36: FALSE | CD36: =+Table1[[#This Row],[Nombres]]&" "&Table1[[#This Row],[Ap_paterno]]&" "&Table1[[#This Row],[Ap_materno]] -> Gerardo Guadalupe Tenopala Hernandez
A37: 1561 | B37: Orozco | C37: Palacios | D37: Noe | E37: 31586 | F37: Morelos | G37: OOPN860623HC3 | H37: Lorenzo Vazquez 3 | I37: Centro Higueron | J37: Jojutla | K37: Morelos | L37: 62906 | M37: México | O37: TRUE | Q37: O | S37: Operativo | T37: 7343454184 | U37: 00000504 | V37: 000000000 | W37: 43143 | X37: 1506862506-8 | Y37: Mexicana | Z37: OOPN860623HMSRLX01 | AA37: 1 | AB37: TRUE | AC37: 43143 | AD37: 43143 | AF37: 43509 | AG37: M | AH37: C | AI37: FALSE | AK37: TRUE | AL37: TRUE | AN37: Manejo | AO37: Manejo | AP37: Manejo | AQ37: noeop23@hotmail.com | AR37: 43509 | AU37: 5256782495996392 | AV37: Banamex | AW37: 42 | AX37: 44 | AY37: 0.0 | BA37: 1 | BB37: 275.78 | BC37: 1 | BD37: FALSE | BF37: 44249 | BG37: M | BJ37: 1094561415 | BK37: 0531098894847 | BM37: 10 | BN37: 7773404329 | BO37: 2 | BP37: N | BR37: FALSE | BT37: Jojutla | BW37: FALSE | BY37: FALSE | CD37: =+Table1[[#This Row],[Nombres]]&" "&Table1[[#This Row],[Ap_paterno]]&" "&Table1[[#This Row],[Ap_materno]] -> Noe Orozco Palacios
A38: 1593 | B38: Garcia | C38: Hernandez | D38: Julio Cesar | E38: 33718 | F38: Hidalgo | G38: GAHJ920424DE5 | H38: Emiliano Zapata SN | I38: Del trabajo | J38: Tepeapulco | K38: Hidalgo | L38: 43976 | M38: México | O38: TRUE | Q38: O | S38: Operativo | T38: 791913274 | V38: D118469-2 | W38: 43248 | X38: 1310921958-7 | Y38: Mexicana | Z38: GAHJ920424HHGRRL07 | AA38: 1 | AB38: TRUE | AC38: 43248 | AD38: 43248 | AF38: 43312 | AG38: M | AH38: U | AI38: FALSE | AK38: TRUE | AL38: TRUE | AN38: Manejo | AO38: Manejo | AP38: Manejo | AQ38: 9204julioc@gmail.com | AR38: 43312 | AU38: 5256782473000993 | AV38: Banamex | AW38: 30 | AX38: 30 | AY38: 25.0 | AZ38: M | BA38: 1 | BB38: 375.43 | BC38: 3 | BD38: FALSE | BF38: 43315 | BG38: M | BM38: 10 | BN38: 7751220805 | BO38: 2 | BP38: N | BT38: Apan | BW38: FALSE | BY38: FALSE | CD38: =+Table1[[#This Row],[Nombres]]&" "&Table1[[#This Row],[Ap_paterno]]&" "&Table1[[#This Row],[Ap_materno]] -> Julio Cesar Garcia Hernandez
A39: 1590 | B39: Arevalo | C39: Villegas | D39: Susana | E39: 36280 | F39: Nuevo León | G39: AEVS990430540 | H39: Rio Amazonas 00112 | I39: Fracc. Mirasur 2 | J39: General de Escobedo | K39: Nuevo Leon | L39: 66070 | M39: México | N39: Licenciatura en Logística | O39: FALSE | Q39: A | S39: Administrativo | T39: 8184752185 | U39: 0000505-0000001 | W39: 43241 | X39: 0216991659-6 | Y39: Mexicana | Z39: AEVS990430MNLRLS04 | AA39: 2 | AB39: TRUE | AC39: 43241 | AD39: 43241 | AF39: 43949 | AG39: F | AH39: S | AI39: FALSE | AK39: FALSE | AL39: TRUE | AN39: Logistica | AO39: Sin experiencia | AP39: logistica y transporte | AQ39: susana30villegas@gmail.com | AR39: 43949 | AU39: 5256783165289092 | AV39: Banamex | AW39: M | AX39: 0 | AY39: 0.0 | BA39: 1 | BB39: 445.24 | BC39: 3 | BD39: FALSE | BF39: 43951 | BG39: M | BJ39: 1596749654 | BK39: 0440118007372 | BM39: 10 | BO39: 5 | BP39: N | BR39: FALSE | BT39: San Nicolas de los Garza | BW39: FALSE | BY39: FALSE | CD39: =+Table1[[#This Row],[Nombres]]&" "&Table1[[#This Row],[Ap_paterno]]&" "&Table1[[#This Row],[Ap_materno]] -> Susana Arevalo Villegas
A40: 1588 | B40: Garcia | C40: Cortes | D40: Efrain | E40: 32695 | F40: México | G40: GACE890706EY2 | H40: 1° de Mayo No 39 A | I40: Las Haciendas | J40: Apan | K40: Hidalgo | L40: 43909 | M40: México | O40: TRUE | Q40: O | S40: Operativo | T40: 2411351238 | V40: 000000 | W40: 43229 | X40: 1306891148-9 | Y40: Mexicana | Z40: GACE890706HMCRRF01 | AA40: 1 | AB40: TRUE | AC40: 43229 | AD40: 43229 | AF40: 43385 | AG40: M | AH40: C | AI40: FALSE | AK40: TRUE | AL40: TRUE | AN40: Manejo | AO40: Manejo | AP40: Manejo | AQ40: efraingar05@gmail.com | AR40: 43385 | AU40: 5256782277318195 | AV40: Banamex | AW40: 34 | AX40: 32 | AY40: 27.0 | AZ40: M | BA40: 1 | BB40: 611.18 | BC40: 3 | BD40: FALSE | BF40: 43391 | BG40: M | BJ40: 1377872421 | BK40: 0135078710898 | BM40: 10 | BO40: 2 | BP40: N | BT40: Ecatepec de Morelos | BW40: FALSE | BY40: FALSE | CD40: =+Table1[[#This Row],[Nombres]]&" "&Table1[[#This Row],[Ap_paterno]]&" "&Table1[[#This Row],[Ap_materno]] -> Efrain Garcia Cortes
...

Sheet TUSA
